
The above exception was the direct cause of the following exception:

Traceback (most recent call last):
  File "c:/Users/Esteban/Documents/GitHub/Rendimiento_Escolar_en_Chile_2010-2019/main.py", line 176, in <module>
    interface.df_to_sql(table_name='alumno', engine=engine, data=data_alumno, headers=headers_alumno, remove_duplicates=['mrun'])
  File "c:\Users\Esteban\Documents\GitHub\Rendimiento_Escolar_en_Chile_2010-2019\interface.py", line 54, in df_to_sql
    new_df.to_sql(table_name,engine, method='multi', if_exists='append',index=False, chunksize=100000)
  File "C:\Users\Esteban\AppData\Local\Packages\PythonSoftwareFoundation.Python.3.7_qbz5n2kfra8p0\LocalCache\local-packages\Python37\site-packages\pandas\core\generic.py", line 2615, in to_sql
    method=method,
  File "C:\Users\Esteban\AppData\Local\Packages\PythonSoftwareFoundation.Python.3.7_qbz5n2kfra8p0\LocalCache\local-packages\Python37\site-packages\pandas\io\sql.py", line 598, in to_sql
    method=method,
  File "C:\Users\Esteban\AppData\Local\Packages\PythonSoftwareFoundation.Python.3.7_qbz5n2kfra8p0\LocalCache\local-packages\Python37\site-packages\pandas\io\sql.py", line 1406, in to_sql
    raise err
  File "C:\Users\Esteban\AppData\Local\Packages\PythonSoftwareFoundation.Python.3.7_qbz5n2kfra8p0\LocalCache\local-packages\Python37\site-packages\pandas\io\sql.py", line 1398, in to_sql
    table.insert(chunksize, method=method)
  File "C:\Users\Esteban\AppData\Local\Packages\PythonSoftwareFoundation.Python.3.7_qbz5n2kfra8p0\LocalCache\local-packages\Python37\site-packages\pandas\io\sql.py", line 830, in insert
    exec_insert(conn, keys, chunk_iter)
  File "C:\Users\Esteban\AppData\Local\Packages\PythonSoftwareFoundation.Python.3.7_qbz5n2kfra8p0\LocalCache\local-packages\Python37\site-packages\pandas\io\sql.py", line 758, in _execute_insert_multi
    conn.execute(self.table.insert(data))
  File "C:\Users\Esteban\AppData\Local\Packages\PythonSoftwareFoundation.Python.3.7_qbz5n2kfra8p0\LocalCache\local-packages\Python37\site-packages\sqlalchemy\engine\base.py", line 1011, in execute
    return meth(self, multiparams, params)
  File "C:\Users\Esteban\AppData\Local\Packages\PythonSoftwareFoundation.Python.3.7_qbz5n2kfra8p0\LocalCache\local-packages\Python37\site-packages\sqlalchemy\sql\elements.py", line 298, in _execute_on_connection
    return connection._execute_clauseelement(self, multiparams, params)
  File "C:\Users\Esteban\AppData\Local\Packages\PythonSoftwareFoundation.Python.3.7_qbz5n2kfra8p0\LocalCache\local-packages\Python37\site-packages\sqlalchemy\engine\base.py", line 1130, in _execute_clauseelement
    distilled_params,
  File "C:\Users\Esteban\AppData\Local\Packages\PythonSoftwareFoundation.Python.3.7_qbz5n2kfra8p0\LocalCache\local-packages\Python37\site-packages\sqlalchemy\engine\base.py", line 1317, in _execute_context
    e, statement, parameters, cursor, context
  File "C:\Users\Esteban\AppData\Local\Packages\PythonSoftwareFoundation.Python.3.7_qbz5n2kfra8p0\LocalCache\local-packages\Python37\site-packages\sqlalchemy\engine\base.py", line 1511, in _handle_dbapi_exception
    sqlalchemy_exception, with_traceback=exc_info[2], from_=e
  File "C:\Users\Esteban\AppData\Local\Packages\PythonSoftwareFoundation.Python.3.7_qbz5n2kfra8p0\LocalCache\local-packages\Python37\site-packages\sqlalchemy\util\compat.py", line 182, in raise_
    raise exception
  File "C:\Users\Esteban\AppData\Local\Packages\PythonSoftwareFoundation.Python.3.7_qbz5n2kfra8p0\LocalCache\local-packages\Python37\site-packages\sqlalchemy\engine\base.py", line 1277, in _execute_context
    cursor, statement, parameters, context
  File "C:\Users\Esteban\AppData\Local\Packages\PythonSoftwareFoundation.Python.3.7_qbz5n2kfra8p0\LocalCache\local-packages\Python37\site-packages\sqlalchemy\engine\default.py", line 593, in do_execute
    cursor.execute(statement, parameters)
sqlalchemy.exc.IntegrityError: (psycopg2.errors.UniqueViolation) llave duplicada viola restricción de unicidad «alumno_pkey»
DETAIL:  Ya existe la llave (mrun)=(7174768).